<?xml version="1.0"?>
<robot xmlns:xacro="http:/www.ros.org/wiki/xacro" name="robot">

<!-- leg -->
<xacro:property name ="leg1_r" value = "0.015"/>
<xacro:property name = "leg1_h" value = "0.15"/>
<xacro:property name = "leg2_r" value = "0.015"/>
<xacro:property name = "leg2_h" value = "0.25"/>
<!--=========-->

<!-- Moment -->
<xacro:property name="mass" value="5"/>
<xacro:property name="Ixx" value="0.01"/>
<xacro:property name="Iyy" value="0.01"/>
<xacro:property name="Izz" value="0.01"/>
<!-- _______________________________________________-->

<xacro:property name="effort" value = "30"/>
<xacro:property name = "base_effort" value = "70"/>
<xacro:property name="velocity" value ="5.0"/>
<xacro:property name="lower" value = "-3.14"/>
<xacro:property name ="upper" value ="3.14"/>
<link name="dummy">

</link>
<joint name="dummy_base" type = "fixed">
	<parent link="dummy"/>
	<child link = "base_link"/>
	
</joint>
<link name = "base_link">
	<visual>
		<origin xyz ="0 0 0" rpy= "0 0 0"/>
		<geometry>
			<box size="0.3 0.3 0.1"/>
		</geometry>
		<material name="white">
        			<color rgba="1 1 1 1"/>
      		</material>
		
	</visual>
	<collision>
		<origin xyz ="0 0 0" rpy= "0 0 0"/>
		<geometry>
			<box size="0.3 0.3 0.1"/>
		</geometry>
		<material name="white">
        			<color rgba="1 1 1 1"/>
      		</material>
		
	</collision>
	<inertial>
		<mass value="${mass}"/>
		<origin xyz="0 0 0"/>
		<inertia ixx="${Ixx}" ixy="0" ixz = "0" iyy="${Iyy}" iyz="0" izz="${Izz}"/>
	</inertial>
</link>
<link name = "box">
	<visual>
		<origin xyz ="0 0 0" rpy= "0 0 0"/>
		<geometry>
			<box size="0.1 0.45 0.1"/>
		</geometry>
		<material name="black">
        			<color rgba="0 0 0 1"/>
      		</material>
		
	</visual>
	<collision>
		<origin xyz ="0 0 0" rpy= "0 0 0"/>
		<geometry>
			<box size="0.1 0.45 0.1"/>
		</geometry>
		<material name="black">
        			<color rgba="0 0 0 1"/>
      		</material>
		
	</collision>
	<inertial>
		<mass value="4"/>
		<origin xyz="0 0 0"/>
		<inertia ixx="${Ixx}" ixy="0" ixz = "0" iyy="${Iyy}" iyz="0" izz="${Izz}"/>
	</inertial>
</link>
<joint name= " box_base_link" type = "fixed">
    	<origin xyz="0 0 0.01" rpy="0 0 0"/>
    	<parent link="base_link"/>
    	<child link="box"/>
</joint>
<!-- =====================================-->
<joint name= "leg1_back1_base_link" type = "revolute">
    	<origin xyz="0.159 -0.165 0" rpy="0 0 -1.57"/>
    	<parent link="base_link"/>
    	<child link="rot_back1_bas"/>
    	<limit effort="${effort}" velocity = "${velocity}" lower = "0" upper="3.14"/>
</joint>
<link name="rot_back1_bas">
	<visual>
		<origin xyz ="0 0 0" rpy= "0 0 0"/>
		<geometry>
			<box size= "0.04 0.04 0.04"/>
		</geometry>
		<material name = "black">
			<color rgba="0.0 0.0 0.0 1.0"/>
		</material>
	</visual>
	<collision>
		<origin xyz ="0 0 0" rpy= "0 0 0"/>
		<geometry>
			<box size= "0.04 0.04 0.04"/>
		</geometry>
		<surface>
          	<friction>
            		<ode>
              			<mu>200.0</mu>
              			<mu2>100.0</mu2>
            		</ode>
          	</friction>
        		</surface>
		<material name = "black">
			<color rgba="0.0 0.0 0.0 1.0"/>
		</material>
	</collision>
	<inertial>
		<mass value="${mass}"/>
		<origin xyz="0 0 0"/>
		<inertia ixx="${Ixx}" ixy="0" ixz = "0" iyy="${Iyy}" iyz="0" izz="${Izz}"/>
	</inertial>
</link>
<joint name = "back1_rot_base" type = "continuous">
	<origin xyz="0.04 0 0" rpy="0 0 1.57"/>
    	<parent link="rot_back1_bas"/>
    	<child link="back1_base_leg"/>
    	<limit effort="${effort}" velocity = "${velocity}" lower = "${lower}" upper="${upper}"/>
</joint>
<link name="back1_base_leg">
	<visual>
		<origin xyz ="0 0 0" rpy= "0 0 0"/>
		<geometry>
			<box size= "0.04 0.04 0.04"/>
		</geometry>
		<material name = "black">
			<color rgba="0.0 0.0 0.0 1.0"/>
		</material>
	</visual>
	<collision>
		<origin xyz ="0 0 0" rpy= "0 0 0"/>
		<geometry>
			<box size= "0.04 0.04 0.04"/>
		</geometry>
		<surface>
          	<friction>
            		<ode>
              			<mu>200.0</mu>
              			<mu2>100.0</mu2>
            		</ode>
          	</friction>
        		</surface>
		<material name = "black">
			<color rgba="0.0 0.0 0.0 1.0"/>
		</material>
	</collision>
	<inertial>
		<mass value="2"/>
		<origin xyz="0 0 0"/>
		<inertia ixx="${Ixx}" ixy="0" ixz = "0" iyy="${Iyy}" iyz="0" izz="${Izz}"/>
	</inertial>
</link>
<joint name= "leg1_back1_base_leg" type = "fixed">
    	<origin xyz="0 0 0" rpy="0 0 0"/>
    	<parent link="back1_base_leg"/>
    	<child link="back1_leg1"/>
    	<limit effort="${effort}" velocity = "${velocity}" lower = "${lower}" upper="${upper}"/>
</joint>
<link name="back1_leg1">
	<visual>
		<origin xyz ="0 -0.05 -0.065" rpy= "-0.729373 0 0"/>
		<geometry>
			<cylinder length="${leg1_h}" radius="${leg1_r}"/>
		</geometry>
		<material name = "white">
			<color rgba="1.0 1.0 1.0 1.0"/>
		</material>
	</visual>
	<collision>
		<origin xyz ="0 -0.05 -0.065" rpy= "-0.729373 0 0"/>
		<geometry>
			<cylinder length="${leg1_h}" radius="${leg1_r}"/>
		</geometry>
		<surface>
          	<friction>
            		<ode>
              			<mu>200.0</mu>
              			<mu2>100.0</mu2>
            		</ode>
          	</friction>
        		</surface>
		<material name = "white">
			<color rgba="1.0 1.0 1.0 1.0"/>
		</material>
	</collision>
	<inertial>
		<mass value="${mass}"/>
		<origin xyz="0 0 0"/>
		<inertia ixx="${Ixx}" ixy="0" ixz = "0" iyy="${Iyy}" iyz="0" izz="${Izz}"/>
	</inertial>
</link>

<link name="back1_joint1">
	<visual>
		<origin xyz ="0 0 0" rpy= "0 0 0"/>
		<geometry>
			<box size= "0.04 0.04 0.04"/>
		</geometry>
		<material name = "black">
			<color rgba="0.0 0.0 0.0 1.0"/>
		</material>
	</visual>
	<collision>
		<origin xyz ="0 0 0" rpy= "0 0 0"/>
		<geometry>
			<box size= "0.04 0.04 0.04"/>
		</geometry>
		<surface>
          	<friction>
            		<ode>
              			<mu>200.0</mu>
              			<mu2>100.0</mu2>
            		</ode>
          	</friction>
        		</surface>
		<material name = "black">
			<color rgba="0.0 0.0 0.0 1.0"/>
		</material>
	</collision>
	<inertial>
		<mass value="1"/>
		<origin xyz="0 0 0"/>
		<inertia ixx="${Ixx}" ixy="0" ixz = "0" iyy="${Iyy}" iyz="0" izz="${Izz}"/>
	</inertial>
</link>

<joint name= "back1_leg1_joint1" type = "continuous">
    	<origin xyz="0 -0.1 -0.1118" rpy="0 0 0"/>
    	<parent link="back1_leg1"/>
    	<child link="back1_joint1"/>
    	<limit effort="${effort}" velocity = "${velocity}" lower = "${lower}" upper="${upper}"/>
</joint>
<link name="back1_leg2">
	<visual>
		<origin xyz ="0 0.045 -0.1118" rpy= "0.411322 0 0"/>
		<geometry>
			<cylinder length="${leg2_h}" radius="${leg2_r}"/>
		</geometry>
		<material name = "white">
			<color rgba="1.0 1.0 1.0 1.0"/>
		</material>
	</visual>
	<collision>
		<origin xyz ="0 0.045 -0.1118" rpy= "0.411322 0 0"/>
		<geometry>
			<cylinder length="${leg2_h}" radius="${leg2_r}"/>
		</geometry>
		<material name = "white">
			<color rgba="1.0 1.0 1.0 1.0"/>
		</material>
	</collision>
	<inertial>
		<mass value="2"/>
		<origin xyz="0 0 0.015"/>
		<inertia ixx="${Ixx}" ixy="0" ixz = "0" iyy="${Iyy}" iyz="0" izz="${Izz}"/>
	</inertial>
</link>
<joint name= " back1_leg2_joint1" type = "fixed">
    	<origin xyz="0 0 0" rpy="0 0 0"/>
    	<parent link="back1_joint1"/>
    	<child link="back1_leg2"/>
</joint>
<link name="back1_roller">
	<visual>
		<origin xyz ="0 0 0" rpy= "0 0 0"/>
		<geometry>
			<box size= "0.03 0.03 0.03"/>
		</geometry>
		<material name = "black">
			<color rgba="0.0 0.0 0.0 1.0"/>
		</material>
	</visual>
	<collision>
		<origin xyz ="0 0 0" rpy= "0 0 0"/>
		<geometry>
			<box size= "0.03 0.04 0.03"/>
		</geometry>
		<material name = "black">
			<color rgba="0.0 0.0 0.0 1.0"/>
		</material>
	</collision>
	<inertial>
		<mass value="1"/>
		<origin xyz="0 0.04 0"/>
		<inertia ixx="${Ixx}" ixy="0" ixz = "0" iyy="${Iyy}" iyz="0" izz="${Izz}"/>
	</inertial>
</link>
<joint name= " back1_leg2_roller" type = "fixed">
    	<origin xyz="0 0.1 -0.22912" rpy="0 0 0"/>
    	<parent link="back1_leg2"/>
    	<child link="back1_roller"/>
</joint>

<!-- ================================= -->
<joint name= "leg1_back2_base_link" type = "revolute">
    	<origin xyz="-0.159 -0.165 0" rpy="0 0 -1.57"/>
    	<parent link="base_link"/>
    	<child link="rot_back2_bas"/>
    	<limit effort="${effort}" velocity = "${velocity}" lower = "-3.14" upper="0"/>
</joint>
<link name="rot_back2_bas">
	<visual>
		<origin xyz ="0 0 0" rpy= "0 0 0"/>
		<geometry>
			<box size= "0.04 0.04 0.04"/>
		</geometry>
		<material name = "black">
			<color rgba="0.0 0.0 0.0 1.0"/>
		</material>
	</visual>
	<collision>
		<origin xyz ="0 0 0" rpy= "0 0 0"/>
		<geometry>
			<box size= "0.04 0.04 0.04"/>
		</geometry>
		<surface>
          	<friction>
            		<ode>
              			<mu>200.0</mu>
              			<mu2>100.0</mu2>
            		</ode>
          	</friction>
        		</surface>
		<material name = "black">
			<color rgba="0.0 0.0 0.0 1.0"/>
		</material>
	</collision>
	<inertial>
		<mass value="${mass}"/>
		<origin xyz="0 0 0"/>
		<inertia ixx="${Ixx}" ixy="0" ixz = "0" iyy="${Iyy}" iyz="0" izz="${Izz}"/>
	</inertial>
</link>
<joint name = "back2_rot_base" type = "continuous">
	<origin xyz="0.04 0 0" rpy="0 0 1.57"/>
    	<parent link="rot_back2_bas"/>
    	<child link="back2_base_leg"/>
    	<limit effort="${effort}" velocity = "${velocity}" lower = "${lower}" upper="${upper}"/>
</joint>
<link name="back2_base_leg">
	<visual>
		<origin xyz ="0 0 0" rpy= "0 0 0"/>
		<geometry>
			<box size= "0.04 0.04 0.04"/>
		</geometry>
		<material name = "black">
			<color rgba="0.0 0.0 0.0 1.0"/>
		</material>
	</visual>
	<collision>
		<origin xyz ="0 0 0" rpy= "0 0 0"/>
		<geometry>
			<box size= "0.04 0.04 0.04"/>
		</geometry>
		<surface>
          	<friction>
            		<ode>
              			<mu>200.0</mu>
              			<mu2>100.0</mu2>
            		</ode>
          	</friction>
        		</surface>
		<material name = "black">
			<color rgba="0.0 0.0 0.0 1.0"/>
		</material>
	</collision>
	<inertial>
		<mass value="2"/>
		<origin xyz="0 0 0"/>
		<inertia ixx="${Ixx}" ixy="0" ixz = "0" iyy="${Iyy}" iyz="0" izz="${Izz}"/>
	</inertial>
</link>
<joint name= "leg1_back2_base_leg" type = "fixed">
    	<origin xyz="0 0 0" rpy="0 0 0"/>
    	<parent link="back2_base_leg"/>
    	<child link="back2_leg1"/>
    	<limit effort="${effort}" velocity = "${velocity}" lower = "${lower}" upper="${upper}"/>
</joint>
<link name="back2_leg1">
	<visual>
		<origin xyz ="0 -0.05 -0.065" rpy= "-0.729373 0 0"/>
		<geometry>
			<cylinder length="${leg1_h}" radius="${leg1_r}"/>
		</geometry>
		<material name = "white">
			<color rgba="1.0 1.0 1.0 1.0"/>
		</material>
	</visual>
	<collision>
		<origin xyz ="0 -0.05 -0.065" rpy= "-0.729373 0 0"/>
		<geometry>
			<cylinder length="${leg1_h}" radius="${leg1_r}"/>
		</geometry>
		<surface>
          	<friction>
            		<ode>
              			<mu>200.0</mu>
              			<mu2>100.0</mu2>
            		</ode>
          	</friction>
        		</surface>
		<material name = "white">
			<color rgba="1.0 1.0 1.0 1.0"/>
		</material>
	</collision>
	<inertial>
		<mass value="${mass}"/>
		<origin xyz="0 0 0"/>
		<inertia ixx="${Ixx}" ixy="0" ixz = "0" iyy="${Iyy}" iyz="0" izz="${Izz}"/>
	</inertial>
</link>

<link name="back2_joint1">
	<visual>
		<origin xyz ="0 0 0" rpy= "0 0 0"/>
		<geometry>
			<box size= "0.04 0.04 0.04"/>
		</geometry>
		<material name = "black">
			<color rgba="0.0 0.0 0.0 1.0"/>
		</material>
	</visual>
	<collision>
		<origin xyz ="0 0 0" rpy= "0 0 0"/>
		<geometry>
			<box size= "0.04 0.04 0.04"/>
		</geometry>
		<surface>
          	<friction>
            		<ode>
              			<mu>200.0</mu>
              			<mu2>100.0</mu2>
            		</ode>
          	</friction>
        		</surface>
		<material name = "black">
			<color rgba="0.0 0.0 0.0 1.0"/>
		</material>
	</collision>
	<inertial>
		<mass value="1"/>
		<origin xyz="0 0 0"/>
		<inertia ixx="${Ixx}" ixy="0" ixz = "0" iyy="${Iyy}" iyz="0" izz="${Izz}"/>
	</inertial>
</link>

<joint name= "back2_leg1_joint1" type = "continuous">
    	<origin xyz="0 -0.1 -0.1118" rpy="0 0 0"/>
    	<parent link="back2_leg1"/>
    	<child link="back2_joint1"/>
    	<limit effort="${effort}" velocity = "${velocity}" lower = "${lower}" upper="${upper}"/>
</joint>
<link name="back2_leg2">
	<visual>
		<origin xyz ="0 0.045 -0.1118" rpy= "0.411322 0 0"/>
		<geometry>
			<cylinder length="${leg2_h}" radius="${leg2_r}"/>
		</geometry>
		<material name = "white">
			<color rgba="1.0 1.0 1.0 1.0"/>
		</material>
	</visual>
	<collision>
		<origin xyz ="0 0.045 -0.1118" rpy= "0.411322 0 0"/>
		<geometry>
			<cylinder length="${leg2_h}" radius="${leg2_r}"/>
		</geometry>
		<material name = "white">
			<color rgba="1.0 1.0 1.0 1.0"/>
		</material>
	</collision>
	<inertial>
		<mass value="2"/>
		<origin xyz="0 0 0.015"/>
		<inertia ixx="${Ixx}" ixy="0" ixz = "0" iyy="${Iyy}" iyz="0" izz="${Izz}"/>
	</inertial>
</link>
<joint name= "back2_leg2_joint1" type = "fixed">
    	<origin xyz="0 0 0" rpy="0 0 0"/>
    	<parent link="back2_joint1"/>
    	<child link="back2_leg2"/>
</joint>
<link name="back2_roller">
	<visual>
		<origin xyz ="0 0 0" rpy= "0 0 0"/>
		<geometry>
			<box size= "0.03 0.03 0.03"/>
		</geometry>
		<material name = "black">
			<color rgba="0.0 0.0 0.0 1.0"/>
		</material>
	</visual>
	<collision>
		<origin xyz ="0 0 0" rpy= "0 0 0"/>
		<geometry>
			<box size= "0.03 0.04 0.03"/>
		</geometry>
		<material name = "black">
			<color rgba="0.0 0.0 0.0 1.0"/>
		</material>
	</collision>
	<inertial>
		<mass value="1"/>
		<origin xyz="0 0.04 0"/>
		<inertia ixx="${Ixx}" ixy="0" ixz = "0" iyy="${Iyy}" iyz="0" izz="${Izz}"/>
	</inertial>
</link>
<joint name= " back2_leg2_roller" type = "fixed">
    	<origin xyz="0 0.1 -0.22912" rpy="0 0 0"/>
    	<parent link="back2_leg2"/>
    	<child link="back2_roller"/>
</joint>
<!-- +============================-->
<joint name="leg1_face1_base_link" type ="revolute">
    	<origin xyz="0.159 0.125 0" rpy="0 0 -1.57"/>
    	<parent link="base_link"/>
    	<child link="rot_face1_bas"/>
    	<limit effort="${effort}" velocity = "${velocity}" lower = "0" upper="3.14"/>
</joint>
<link name="rot_face1_bas">
	<visual>
		<origin xyz ="0 0 0" rpy= "0 0 0"/>
		<geometry>
			<box size= "0.04 0.04 0.04"/>
		</geometry>
		<material name = "black">
			<color rgba="0.0 0.0 0.0 1.0"/>
		</material>
	</visual>
	<collision>
		<origin xyz ="0 0 0" rpy= "0 0 0"/>
		<geometry>
			<box size= "0.04 0.04 0.04"/>
		</geometry>
		<surface>
          	<friction>
            		<ode>
              			<mu>200.0</mu>
              			<mu2>100.0</mu2>
            		</ode>
          	</friction>
        		</surface>
		<material name = "black">
			<color rgba="0.0 0.0 0.0 1.0"/>
		</material>
	</collision>
	<inertial>
		<mass value="${mass}"/>
		<origin xyz="0 0 0"/>
		<inertia ixx="${Ixx}" ixy="0" ixz = "0" iyy="${Iyy}" iyz="0" izz="${Izz}"/>
	</inertial>
</link>
<joint name = "face1_rot_base" type = "continuous">
	<origin xyz="-0.04 0 0" rpy="0 0 1.57"/>
    	<parent link="rot_face1_bas"/>
    	<child link="face1_base_leg"/>
    	<limit effort="${effort}" velocity = "${velocity}" lower = "${lower}" upper="${upper}"/>
</joint>
<link name="face1_base_leg">
	<visual>
		<origin xyz ="0 0 0" rpy= "0 0 0"/>
		<geometry>
			<box size= "0.04 0.04 0.04"/>
		</geometry>
		<material name = "black">
			<color rgba="0.0 0.0 0.0 1.0"/>
		</material>
	</visual>
	<collision>
		<origin xyz ="0 0 0" rpy= "0 0 0"/>
		<geometry>
			<box size= "0.04 0.04 0.04"/>
		</geometry>
		<surface>
          	<friction>
            		<ode>
              			<mu>200.0</mu>
              			<mu2>100.0</mu2>
            		</ode>
          	</friction>
        		</surface>
		<material name = "black">
			<color rgba="0.0 0.0 0.0 1.0"/>
		</material>
	</collision>
	<inertial>
		<mass value="2"/>
		<origin xyz="0 0 0"/>
		<inertia ixx="${Ixx}" ixy="0" ixz = "0" iyy="${Iyy}" iyz="0" izz="${Izz}"/>
	</inertial>
</link>
<joint name= "leg1_face1_base_leg" type = "fixed">
    	<origin xyz="0 0 0" rpy="0 0 0"/>
    	<parent link="face1_base_leg"/>
    	<child link="face1_leg1"/>
    	<limit effort="${effort}" velocity = "${velocity}" lower = "${lower}" upper="${upper}"/>
</joint>
<link name="face1_leg1">
	<visual>
		<origin xyz ="0 -0.05 -0.065" rpy= "-0.729373 0 0"/>
		<geometry>
			<cylinder length="${leg1_h}" radius="${leg1_r}"/>
		</geometry>
		<material name = "white">
			<color rgba="1.0 1.0 1.0 1.0"/>
		</material>
	</visual>
	<collision>
		<origin xyz ="0 -0.05 -0.065" rpy= "-0.729373 0 0"/>
		<geometry>
			<cylinder length="${leg1_h}" radius="${leg1_r}"/>
		</geometry>
		<surface>
          	<friction>
            		<ode>
              			<mu>200.0</mu>
              			<mu2>100.0</mu2>
            		</ode>
          	</friction>
        		</surface>
		<material name = "white">
			<color rgba="1.0 1.0 1.0 1.0"/>
		</material>
	</collision>
	<inertial>
		<mass value="${mass}"/>
		<origin xyz="0 0 0"/>
		<inertia ixx="${Ixx}" ixy="0" ixz = "0" iyy="${Iyy}" iyz="0" izz="${Izz}"/>
	</inertial>
</link>

<link name="face1_joint1">
	<visual>
		<origin xyz ="0 0 0" rpy= "0 0 0"/>
		<geometry>
			<box size= "0.04 0.04 0.04"/>
		</geometry>
		<material name = "black">
			<color rgba="0.0 0.0 0.0 1.0"/>
		</material>
	</visual>
	<collision>
		<origin xyz ="0 0 0" rpy= "0 0 0"/>
		<geometry>
			<box size= "0.04 0.04 0.04"/>
		</geometry>
		<surface>
          	<friction>
            		<ode>
              			<mu>200.0</mu>
              			<mu2>100.0</mu2>
            		</ode>
          	</friction>
        		</surface>
		<material name = "black">
			<color rgba="0.0 0.0 0.0 1.0"/>
		</material>
	</collision>
	<inertial>
		<mass value="1"/>
		<origin xyz="0 0 0"/>
		<inertia ixx="${Ixx}" ixy="0" ixz = "0" iyy="${Iyy}" iyz="0" izz="${Izz}"/>
	</inertial>
</link>

<joint name= "face1_leg1_joint1" type = "continuous">
    	<origin xyz="0 -0.1 -0.1118" rpy="0 0 0"/>
    	<parent link="face1_leg1"/>
    	<child link="face1_joint1"/>
    	<limit effort="${effort}" velocity = "${velocity}" lower = "${lower}" upper="${upper}"/>
</joint>
<link name="face1_leg2">
	<visual>
		<origin xyz ="0 0.045 -0.1118" rpy= "0.411322 0 0"/>
		<geometry>
			<cylinder length="${leg2_h}" radius="${leg2_r}"/>
		</geometry>
		<material name = "white">
			<color rgba="1.0 1.0 1.0 1.0"/>
		</material>
	</visual>
	<collision>
		<origin xyz ="0 0.045 -0.1118" rpy= "0.411322 0 0"/>
		<geometry>
			<cylinder length="${leg2_h}" radius="${leg2_r}"/>
		</geometry>
		<material name = "white">
			<color rgba="1.0 1.0 1.0 1.0"/>
		</material>
	</collision>
	<inertial>
		<mass value="2"/>
		<origin xyz="0 0 0.015"/>
		<inertia ixx="${Ixx}" ixy="0" ixz = "0" iyy="${Iyy}" iyz="0" izz="${Izz}"/>
	</inertial>
</link>
<joint name= "face1_leg2_joint1" type = "fixed">
    	<origin xyz="0 0 0" rpy="0 0 0"/>
    	<parent link="face1_joint1"/>
    	<child link="face1_leg2"/>
</joint>
<link name="face1_roller">
	<visual>
		<origin xyz ="0 0 0" rpy= "0 0 0"/>
		<geometry>
			<box size= "0.03 0.03 0.03"/>
		</geometry>
		<material name = "black">
			<color rgba="0.0 0.0 0.0 1.0"/>
		</material>
	</visual>
	<collision>
		<origin xyz ="0 0 0" rpy= "0 0 0"/>
		<geometry>
			<box size= "0.03 0.04 0.03"/>
		</geometry>
		<material name = "black">
			<color rgba="0.0 0.0 0.0 1.0"/>
		</material>
	</collision>
	<inertial>
		<mass value="1"/>
		<origin xyz="0 0.04 0"/>
		<inertia ixx="${Ixx}" ixy="0" ixz = "0" iyy="${Iyy}" iyz="0" izz="${Izz}"/>
	</inertial>
</link>
<joint name= " face1_leg2_roller" type = "fixed">
    	<origin xyz="0 0.1 -0.22912" rpy="0 0 0"/>
    	<parent link="face1_leg2"/>
    	<child link="face1_roller"/>
</joint>
<!-- +============================-->
<joint name= "leg1_face2_base_link" type = "revolute">
    	<origin xyz="-0.159 0.125 0" rpy="0 0 -1.57"/>
    	<parent link="base_link"/>
    	<child link="rot_face2_bas"/>
    	<limit effort="${effort}" velocity = "${velocity}" lower = "-3.14" upper="0"/>
</joint>
<link name="rot_face2_bas">
	<visual>
		<origin xyz ="0 0 0" rpy= "0 0 0"/>
		<geometry>
			<box size= "0.04 0.04 0.04"/>
		</geometry>
		<material name = "black">
			<color rgba="0.0 0.0 0.0 1.0"/>
		</material>
	</visual>
	<collision>
		<origin xyz ="0 0 0" rpy= "0 0 0"/>
		<geometry>
			<box size= "0.04 0.04 0.04"/>
		</geometry>
		<surface>
          	<friction>
            		<ode>
              			<mu>200.0</mu>
              			<mu2>100.0</mu2>
            		</ode>
          	</friction>
        		</surface>
		<material name = "black">
			<color rgba="0.0 0.0 0.0 1.0"/>
		</material>
	</collision>
	<inertial>
		<mass value="${mass}"/>
		<origin xyz="0 0 0"/>
		<inertia ixx="${Ixx}" ixy="0" ixz = "0" iyy="${Iyy}" iyz="0" izz="${Izz}"/>
	</inertial>
</link>
<joint name = "face2_rot_base" type = "continuous">
	<origin xyz="-0.04 0 0" rpy="0 0 1.57"/>
    	<parent link="rot_face2_bas"/>
    	<child link="face2_base_leg"/>
    	<limit effort="${effort}" velocity = "${velocity}" lower = "${lower}" upper="${upper}"/>
</joint>
<link name="face2_base_leg">
	<visual>
		<origin xyz ="0 0 0" rpy= "0 0 0"/>
		<geometry>
			<box size= "0.04 0.04 0.04"/>
		</geometry>
		<material name = "black">
			<color rgba="0.0 0.0 0.0 1.0"/>
		</material>
	</visual>
	<collision>
		<origin xyz ="0 0 0" rpy= "0 0 0"/>
		<geometry>
			<box size= "0.04 0.04 0.04"/>
		</geometry>
		<surface>
          	<friction>
            		<ode>
              			<mu>200.0</mu>
              			<mu2>100.0</mu2>
            		</ode>
          	</friction>
        		</surface>
		<material name = "black">
			<color rgba="0.0 0.0 0.0 1.0"/>
		</material>
	</collision>
	<inertial>
		<mass value="2"/>
		<origin xyz="0 0 0"/>
		<inertia ixx="${Ixx}" ixy="0" ixz = "0" iyy="${Iyy}" iyz="0" izz="${Izz}"/>
	</inertial>
</link>
<joint name= " leg1_face2_base_leg" type = "fixed">
    	<origin xyz="0 0 0" rpy="0 0 0"/>
    	<parent link="face2_base_leg"/>
    	<child link="face2_leg1"/>
    	<limit effort="${effort}" velocity = "${velocity}" lower = "${lower}" upper="${upper}"/>
</joint>
<link name="face2_leg1">
	<visual>
		<origin xyz ="0 -0.05 -0.065" rpy= "-0.729373 0 0"/>
		<geometry>
			<cylinder length="${leg1_h}" radius="${leg1_r}"/>
		</geometry>
		<material name = "white">
			<color rgba="1.0 1.0 1.0 1.0"/>
		</material>
	</visual>
	<collision>
		<origin xyz ="0 -0.05 -0.065" rpy= "-0.729373 0 0"/>
		<geometry>
			<cylinder length="${leg1_h}" radius="${leg1_r}"/>
		</geometry>
		<surface>
          	<friction>
            		<ode>
              			<mu>200.0</mu>
              			<mu2>100.0</mu2>
            		</ode>
          	</friction>
        		</surface>
		<material name = "white">
			<color rgba="1.0 1.0 1.0 1.0"/>
		</material>
	</collision>
	<inertial>
		<mass value="${mass}"/>
		<origin xyz="0 0 0"/>
		<inertia ixx="${Ixx}" ixy="0" ixz = "0" iyy="${Iyy}" iyz="0" izz="${Izz}"/>
	</inertial>
</link>

<link name="face2_joint1">
	<visual>
		<origin xyz ="0 0 0" rpy= "0 0 0"/>
		<geometry>
			<box size= "0.04 0.04 0.04"/>
		</geometry>
		<material name = "black">
			<color rgba="0.0 0.0 0.0 1.0"/>
		</material>
	</visual>
	<collision>
		<origin xyz ="0 0 0" rpy= "0 0 0"/>
		<geometry>
			<box size= "0.04 0.04 0.04"/>
		</geometry>
		<surface>
          	<friction>
            		<ode>
              			<mu>200.0</mu>
              			<mu2>100.0</mu2>
            		</ode>
          	</friction>
        		</surface>
		<material name = "black">
			<color rgba="0.0 0.0 0.0 1.0"/>
		</material>
	</collision>
	<inertial>
		<mass value="1"/>
		<origin xyz="0 0 0"/>
		<inertia ixx="${Ixx}" ixy="0" ixz = "0" iyy="${Iyy}" iyz="0" izz="${Izz}"/>
	</inertial>
</link>

<joint name= "face2_leg1_joint1" type = "continuous">
    	<origin xyz="0 -0.1 -0.1118" rpy="0 0 0"/>
    	<parent link="face2_leg1"/>
    	<child link="face2_joint1"/>
    	<limit effort="${effort}" velocity = "${velocity}"/>
</joint>
<link name="face2_leg2">
	<visual>
		<origin xyz ="0 0.045 -0.1118" rpy= "0.411322 0 0"/>
		<geometry>
			<cylinder length="${leg2_h}" radius="${leg2_r}"/>
		</geometry>
		<material name = "white">
			<color rgba="1.0 1.0 1.0 1.0"/>
		</material>
	</visual>
	<collision>
		<origin xyz ="0 0.045 -0.1118" rpy= "0.411322 0 0"/>
		<geometry>
			<cylinder length="${leg2_h}" radius="${leg2_r}"/>
		</geometry>
		<material name = "white">
			<color rgba="1.0 1.0 1.0 1.0"/>
		</material>
	</collision>
	<inertial>
		<mass value="2"/>
		<origin xyz="0 0 0.015"/>
		<inertia ixx="${Ixx}" ixy="0" ixz = "0" iyy="${Iyy}" iyz="0" izz="${Izz}"/>
	</inertial>
</link>
<joint name= " face2_leg2_joint1" type = "fixed">
    	<origin xyz="0 0 0" rpy="0 0 0"/>
    	<parent link="face2_joint1"/>
    	<child link="face2_leg2"/>
</joint>
<link name="face2_roller">
	<visual>
		<origin xyz ="0 0 0" rpy= "0 0 0"/>
		<geometry>
			<box size= "0.03 0.03 0.03"/>
		</geometry>
		<material name = "black">
			<color rgba="0.0 0.0 0.0 1.0"/>
		</material>
	</visual>
	<collision>
		<origin xyz ="0 0 0" rpy= "0 0 0"/>
		<geometry>
			<box size= "0.03 0.04 0.03"/>
		</geometry>
		<material name = "black">
			<color rgba="0.0 0.0 0.0 1.0"/>
		</material>
	</collision>
	<inertial>
		<mass value="1"/>
		<origin xyz="0 0.04 0"/>
		<inertia ixx="${Ixx}" ixy="0" ixz = "0" iyy="${Iyy}" iyz="0" izz="${Izz}"/>
	</inertial>
</link>
<joint name= " face2_leg2_roller" type = "fixed">
    	<origin xyz="0 0.1 -0.22912" rpy="0 0 0"/>
    	<parent link="face2_leg2"/>
    	<child link="face2_roller"/>
</joint>
<gazebo reference="base_link">
	<material>Gazebo/Black</material>
	<turnGravityOff>false</turnGravityOff>
</gazebo>


<!-- transmission -->
<transmission name = "back1_tran1">
	<type>transmission_interface/SimpleTransmission</type>
	<joint name = "leg1_back1_base_link">
		<hardwareInterface>hardware_interface/EffortJointInterface</hardwareInterface>
	</joint>
	<actuator name= "motor1">
		<hardwareInterface>hardware_interface/EffortJointInterface</hardwareInterface>
      		<mechanicalReduction>1</mechanicalReduction>
	</actuator>
</transmission>
<transmission name = "back1_tran2">
	<type>transmission_interface/SimpleTransmission</type>
	<joint name = "back1_rot_base">
		<hardwareInterface>hardware_interface/EffortJointInterface</hardwareInterface>
	</joint>
	<actuator name= "motor2">
		<hardwareInterface>hardware_interface/EffortJointInterface</hardwareInterface>
		<mechanicalReduction>1</mechanicalReduction>
	</actuator>
</transmission>
<transmission name = "back1_tran3">
	<type>transmission_interface/SimpleTransmission</type>
	<joint name = "back1_leg1_joint1">
		<hardwareInterface>hardware_interface/EffortJointInterface</hardwareInterface>
	</joint>
	<actuator name= "motor3">
		<hardwareInterface>hardware_interface/EffortJointInterface</hardwareInterface>
		<mechanicalReduction>1</mechanicalReduction>
	</actuator>
</transmission>

<transmission name = "back2_tran1">
	<type>transmission_interface/SimpleTransmission</type>
	<joint name = "leg1_back2_base_link">
		<hardwareInterface>hardware_interface/EffortJointInterface</hardwareInterface>
	</joint>
	<actuator name= "motor4">
		<hardwareInterface>hardware_interface/EffortJointInterface</hardwareInterface>
		<mechanicalReduction>1</mechanicalReduction>
	</actuator>
</transmission>
<transmission name = "back2_tran2">
	<type>transmission_interface/SimpleTransmission</type>
	<joint name = "back2_rot_base">
		<hardwareInterface>hardware_interface/EffortJointInterface</hardwareInterface>
	</joint>
	<actuator name= "motor5">
		<hardwareInterface>hardware_interface/EffortJointInterface</hardwareInterface>
		<mechanicalReduction>1</mechanicalReduction>
	</actuator>
</transmission>
<transmission name = "back2_tran3">
	<type>transmission_interface/SimpleTransmission</type>
	<joint name = "back2_leg1_joint1">
		<hardwareInterface>hardware_interface/EffortJointInterface</hardwareInterface>
	</joint>
	<actuator name= "motor6">
		<hardwareInterface>hardware_interface/EffortJointInterface</hardwareInterface>
		<mechanicalReduction>1</mechanicalReduction>
	</actuator>
</transmission>

<transmission name = "face1_tran1">
	<type>transmission_interface/SimpleTransmission</type>
	<joint name = "leg1_face1_base_link">
		<hardwareInterface>hardware_interface/EffortJointInterface</hardwareInterface>
	</joint>
	<actuator name= "motor7">
		<hardwareInterface>hardware_interface/EffortJointInterface</hardwareInterface>
		<mechanicalReduction>1</mechanicalReduction>
	</actuator>
</transmission>
<transmission name = "face1_tran2">
	<type>transmission_interface/SimpleTransmission</type>
	<joint name = "face1_rot_base">
		<hardwareInterface>hardware_interface/EffortJointInterface</hardwareInterface>
	</joint>
	<actuator name= "motor8">
		<hardwareInterface>hardware_interface/EffortJointInterface</hardwareInterface>
		<mechanicalReduction>1</mechanicalReduction>
	</actuator>
</transmission>
<transmission name = "face1_tran3">
	<type>transmission_interface/SimpleTransmission</type>
	<joint name = "face1_leg1_joint1">
		<hardwareInterface>hardware_interface/EffortJointInterface</hardwareInterface>
	</joint>
	<actuator name= "motor9">
		<hardwareInterface>hardware_interface/EffortJointInterface</hardwareInterface>
		<mechanicalReduction>1</mechanicalReduction>
	</actuator>
</transmission>

<transmission name = "face2_tran1">
	<type>transmission_interface/SimpleTransmission</type>
	<joint name = "leg1_face2_base_link">
		<hardwareInterface>hardware_interface/EffortJointInterface</hardwareInterface>
	</joint>
	<actuator name= "motor10">
		<hardwareInterface>hardware_interface/EffortJointInterface</hardwareInterface>
		<mechanicalReduction>1</mechanicalReduction>
	</actuator>
</transmission>
<transmission name = "face2_tran2">
	<type>transmission_interface/SimpleTransmission</type>
	<joint name = "face2_rot_base">
		<hardwareInterface>hardware_interface/EffortJointInterface</hardwareInterface>
	</joint>
	<actuator name= "motor11">
		<hardwareInterface>hardware_interface/EffortJointInterface</hardwareInterface>
		<mechanicalReduction>1</mechanicalReduction>
	</actuator>
</transmission>
<transmission name = "face2_tran3">
	<type>transmission_interface/SimpleTransmission</type>
	<joint name = "face2_leg1_joint1">
		<hardwareInterface>hardware_interface/EffortJointInterface</hardwareInterface>
	</joint>
	<actuator name= "motor12">
		<hardwareInterface>hardware_interface/EffortJointInterface</hardwareInterface>
		<mechanicalReduction>1</mechanicalReduction>
	</actuator>
</transmission>

<gazebo>
    <plugin name="gazebo_ros_control" filename="libgazebo_ros_control.so">
      <robotNamespace>/dog_robot</robotNamespace>
      <robotSimType>gazebo_ros_control/DefaultRobotHWSim</robotSimType>
    </plugin>
</gazebo>
</robot>
