<?xml version="1.0"?>
<robot xmlns:xacro="http:/www.ros.org/wiki/xacro" name="robot">

<!-- leg -->
<xacro:property name ="leg1_r" value = "0.015"/>
<xacro:property name = "leg1_h" value = "0.15"/>
<xacro:property name = "leg2_r" value = "0.015"/>
<xacro:property name = "leg2_h" value = "0.25"/>
<!--=========-->
<xacro:macro name="leg2" params="prefix reflect">
<link name="${prefix}_base_leg">
	<visual>
		<origin xyz ="0 0 0" rpy= "0 0 0"/>
		<geometry>
			<box size= "0.04 0.04 0.04"/>
		</geometry>
		<material name = "black">
			<color rgba="0.0 0.0 0.0 1.0"/>
		</material>
	</visual>
</link>
<joint name= " leg1_${prefix}_base_leg" type = "continuous">
    	<origin xyz="${reflect*0.15} 0 0" rpy="0 0 0"/>
    	<parent link="${prefix}_base_leg"/>
    	<child link="${prefix}_leg1"/>
</joint>
<link name="${prefix}_leg1">
	<visual>
		<origin xyz ="0 -0.05 -0.065" rpy= "-0.729373 0 0"/>
		<geometry>
			<cylinder length="${leg1_h}" radius="${leg1_r}"/>
		</geometry>
		<material name = "white">
			<color rgba="1.0 1.0 1.0 1.0"/>
		</material>
	</visual>
</link>

<link name="${prefix}_joint1">
	<visual>
		<origin xyz ="0 0 0" rpy= "0 0 0"/>
		<geometry>
			<box size= "0.04 0.04 0.04"/>
		</geometry>
		<material name = "black">
			<color rgba="0.0 0.0 0.0 1.0"/>
		</material>
	</visual>
</link>

<joint name= " ${prefix}_leg1_joint1" type = "continuous">
    	<origin xyz="0 -0.1 -0.1118" rpy="0 0 0"/>
    	<parent link="${prefix}_leg1"/>
    	<child link="${prefix}_joint1"/>
</joint>
<link name="${prefix}_leg22">
	<visual>
		<origin xyz ="0 0.045 -0.1118" rpy= "0.411322 0 0"/>
		<geometry>
			<cylinder length="${leg2_h}" radius="${leg2_r}"/>
		</geometry>
		<material name = "white">
			<color rgba="1.0 1.0 1.0 1.0"/>
		</material>
	</visual>
</link>
<joint name= " ${prefix}_leg22_joint1" type = "fixed">
    	<origin xyz="0 0 0" rpy="0 0 0"/>
    	<parent link="${prefix}_joint1"/>
    	<child link="${prefix}_leg22"/>
</joint>
<link name="${prefix}_roller1">
	<visual>
		<origin xyz ="0 0 0" rpy= "0 0 0"/>
		<geometry>
			<sphere radius="0.03"/>
		</geometry>
		<material name = "black">
			<color rgba="0.0 0.0 0.0 1.0"/>
		</material>
	</visual>
</link>
<joint name= " ${prefix}_leg22_roller1" type = "fixed">
    	<origin xyz="0 0.1 -0.22912" rpy="0 0 0"/>
    	<parent link="${prefix}_leg22"/>
    	<child link="${prefix}_roller1"/>
</joint>
</robot>
